Workbook

Sheet README
B2: LNNCP Early-Warning Dashboard -- Methodology
B4: This workbook is fully formula-driven (no macros). All statistics recalculate live in Excel
B5: whenever you edit or append rows in Raw_Data / Analysis.
B7: Sheets:
B8: Dashboard - KPI summary, status distribution chart, control-band chart.
B9: Analysis - one row per day, every statistical method computed as native Excel formulas.
B10: Alert_Log - live filtered list of every day flagged WATCH / EARLY WARNING / CRITICAL,
B11: most recent first (uses FILTER + SORT + HSTACK).
B12: Raw_Data - source series as loaded from anomaly_detection_input.csv.
B14: Methods combined in the Analysis sheet (rolling 30-day window, 10-day minimum history):
B16: 1. Shewhart control bands: UCL/LCL = rolling mean +/- 3 x rolling std dev.
B17: 2. Z-Score: (value - rolling mean) / rolling std dev. |Z| > 2 = early warning, |Z| > 3 = critical.
... B42: negative than recent history).

Sheet Dashboard
B2: LNNCP Early-Warning Monitoring Dashboard
B3: Statistical process-control early warning (rolling z-score, robust MAD z-score, EWMA, CUSUM)
B4: =CONCAT("Data range: ",TEXT(INDEX(Analysis!A:A,2),"dd-mmm-yyyy")," to ",TEXT(INDEX(Analysis!A:A,COUNTA(Analysis!A:A)),"dd-mmm-yyyy")," | ",COUNTA(Analysis!A:A)-1," observations")
B6: Latest Date | E6: Latest Value | H6: Latest Status | K6: Latest Z-Score
B7: =INDEX(Analysis!A:A,COUNTA(Analysis!A:A)) | E7: =INDEX(Analysis!B:B,COUNTA(Analysis!A:A)) | H7: =INDEX(Analysis!Q:Q,COUNTA(Analysis!A:A)) | K7: =INDEX(Analysis!G:G,COUNTA(Analysis!A:A))
B10: Days Since Last Critical | E10: Critical Alerts (All-Time) | H10: Early Warnings (All-Time) | K10: Alerts in Last 90 Days
B11: =IF(COUNTIF(Analysis!Q:Q,"CRITICAL")=0,"None yet",INDEX(Analysis!A:A,COUNTA(Analysis!A:A))-MAXIFS(Analysis!A2:A644,Analysis!Q2:Q644,"CRITICAL")) | E11: =COUNTIF(Analysis!Q:Q,"CRITICAL") | H11: =COUNTIF(Analysis!Q:Q,"EARLY WARNING") | K11: =COUNTIFS(Analysis!A:A,">="&(INDEX(Analysis!A:A,COUNTA(Analysis!A:A))-90),Analysis!Q:Q,"CRITICAL")+COUNTIFS(Analysis!A:A,">="&(INDEX(Analysis!A:A,COUNTA(Analysis!A:A))-90),Analysis!Q:Q,"EARLY WARNING")
B14: 14-Day EWMA Trend
B15: =IF(INDEX(Analysis!K:K,COUNTA(Analysis!A:A))>INDEX(Analysis!K:K,COUNTA(Analysis!A:A)-14),"Rising",IF(INDEX(Analysis!K:K,COUNTA(Analysis!A:A))<INDEX(Analysis!K:K,COUNTA(Analysis!A:A)-14),"Falling","Stable"))
B16: Status | C16: Count (All-Time)
B17: NORMAL | C17: =COUNTIF(Analysis!Q:Q,"NORMAL")
B18: WATCH | C18: =COUNTIF(Analysis!Q:Q,"WATCH")
B19: EARLY WARNING | C19: =COUNTIF(Analysis!Q:Q,"EARLY WARNING")
B20: CRITICAL | C20: =COUNTIF(Analysis!Q:Q,"CRITICAL")

Sheet Raw_Data
A1: Date | B1: lnncp
A2: 45027 | B2: -5112.21
A3: 45028 | B3: -13758.91
A4: 45029 | B4: -1122.35
A5: 45030 | B5: -8569.06
A6: 45031 | B6: -781.68
A7: 45032 | B7: -1021.88
A8: 45033 | B8: -1528.81
A9: 45034 | B9: -189.69
A10: 45035 | B10: -299.93
A11: 45036 | B11: -3465.54
A12: 45037 | B12: -5109.97
A13: 45038 | B13: -5750.89
... A644: 45669 | B644: -6847.47

Sheet Analysis
A1: Date | B1: Value | C1: Rolling_Mean_30 | D1: Rolling_Std_30 | E1: UCL_3sigma | F1: LCL_3sigma | G1: Z_Score | H1: Rolling_Median_30 | I1: MAD_30 | J1: Robust_Z | K1: EWMA | L1: EWMA_UCL | M1: EWMA_LCL | N1: CUSUM_Pos | O1: CUSUM_Neg | P1: Consec_Breach | Q1: Status
A2: 45027 | B2: =Raw_Data!B2 | K2: =B2 | Q2: Insufficient History
A3: 45028 | B3: =Raw_Data!B3 | K3: =0.2*B3+0.8*K2 | Q3: Insufficient History
A4: 45029 | B4: =Raw_Data!B4 | K4: =0.2*B4+0.8*K3 | Q4: Insufficient History
A5: 45030 | B5: =Raw_Data!B5 | K5: =0.2*B5+0.8*K4 | Q5: Insufficient History
A6: 45031 | B6: =Raw_Data!B6 | K6: =0.2*B6+0.8*K5 | Q6: Insufficient History
A7: 45032 | B7: =Raw_Data!B7 | K7: =0.2*B7+0.8*K6 | Q7: Insufficient History
A8: 45033 | B8: =Raw_Data!B8 | K8: =0.2*B8+0.8*K7 | Q8: Insufficient History
A9: 45034 | B9: =Raw_Data!B9 | K9: =0.2*B9+0.8*K8 | Q9: Insufficient History
A10: 45035 | B10: =Raw_Data!B10 | K10: =0.2*B10+0.8*K9 | Q10: Insufficient History
A11: 45036 | B11: =Raw_Data!B11 | C11: =AVERAGE(B2:B11) | D11: =STDEV.S(B2:B11) | E11: =C11+3*D11 | F11: =C11-3*D11 | G11: =IF(D11=0,"",(B11-C11)/D11) | H11: =MEDIAN(B2:B11) | I11: =MEDIAN(ABS(B2:B11-H11)) | J11: =IF(I11=0,"",0.6745*(B11-H11)/I11) | K11: =0.2*B11+0.8*K10 | L11: =C11+3*D11*SQRT(0.2/(2-0.2)) | M11: =C11-3*D11*SQRT(0.2/(2-0.2)) | N11: =MAX(0,B11-C11-0.5*D11) | O11: =MIN(0,B11-C11+0.5*D11) | P11: =IF(ABS(G11)>1,1,0) | Q11: =IFS(OR(ABS(G11)>3,N11>5*D11,ABS(O11)>5*D11,P11>=5),"CRITICAL",OR(ABS(G11)>2,P11>=3,ABS(J11)>3.5),"EARLY WARNING",ABS(G11)>1,"WATCH",TRUE,"NORMAL")
A12: 45037 | B12: =Raw_Data!B12 | C12: =AVERAGE(B2:B12) | D12: =STDEV.S(B2:B12) | E12: =C12+3*D12 | F12: =C12-3*D12 | G12: =IF(D12=0,"",(B12-C12)/D12) | H12: =MEDIAN(B2:B12) | I12: =MEDIAN(ABS(B2:B12-H12)) | J12: =IF(I12=0,"",0.6745*(B12-H12)/I12) | K12: =0.2*B12+0.8*K11 | L12: =C12+3*D12*SQRT(0.2/(2-0.2)) | M12: =C12-3*D12*SQRT(0.2/(2-0.2)) | N12: =MAX(0,N11+(B12-C12-0.5*D12)) | O12: =MIN(0,O11+(B12-C12+0.5*D12)) | P12: =IF(ABS(G12)>1,P11+1,0) | Q12: =IFS(OR(ABS(G12)>3,N12>5*D12,ABS(O12)>5*D12,P12>=5),"CRITICAL",OR(ABS(G12)>2,P12>=3,ABS(J12)>3.5),"EARLY WARNING",ABS(G12)>1,"WATCH",TRUE,"NORMAL")
A13: 45038 | B13: =Raw_Data!B13 | C13: =AVERAGE(B2:B13) | D13: =STDEV.S(B2:B13) | E13: =C13+3*D13 | F13: =C13-3*D13 | G13: =IF(D13=0,"",(B13-C13)/D13) | H13: =MEDIAN(B2:B13) | I13: =MEDIAN(ABS(B2:B13-H13)) | J13: =IF(I13=0,"",0.6745*(B13-H13)/I13) | K13: =0.2*B13+0.8*K12 | L13: =C13+3*D13*SQRT(0.2/(2-0.2)) | M13: =C13-3*D13*SQRT(0.2/(2-0.2)) | N13: =MAX(0,N12+(B13-C13-0.5*D13)) | O13: =MIN(0,O12+(B13-C13+0.5*D13)) | P13: =IF(ABS(G13)>1,P12+1,0) | Q13: =IFS(OR(ABS(G13)>3,N13>5*D13,ABS(O13)>5*D13,P13>=5),"CRITICAL",OR(ABS(G13)>2,P13>=3,ABS(J13)>3.5),"EARLY WARNING",ABS(G13)>1,"WATCH",TRUE,"NORMAL")
A14: 45039 | B14: =Raw_Data!B14 | C14: =AVERAGE(B2:B14) | D14: =STDEV.S(B2:B14) | E14: =C14+3*D14 | F14: =C14-3*D14 | G14: =IF(D14=0,"",(B14-C14)/D14) | H14: =MEDIAN(B2:B14) | I14: =MEDIAN(ABS(B2:B14-H14)) | J14: =IF(I14=0,"",0.6745*(B14-H14)/I14) | K14: =0.2*B14+0.8*K13 | L14: =C14+3*D14*SQRT(0.2/(2-0.2)) | M14: =C14-3*D14*SQRT(0.2/(2-0.2)) | N14: =MAX(0,N13+(B14-C14-0.5*D14)) | O14: =MIN(0,O13+(B14-C14+0.5*D14)) | P14: =IF(ABS(G14)>1,P13+1,0) | Q14: =IFS(OR(ABS(G14)>3,N14>5*D14,ABS(O14)>5*D14,P14>=5),"CRITICAL",OR(ABS(G14)>2,P14>=3,ABS(J14)>3.5),"EARLY WARNING",ABS(G14)>1,"WATCH",TRUE,"NORMAL")
A15: 45040 | B15: =Raw_Data!B15 | C15: =AVERAGE(B2:B15) | D15: =STDEV.S(B2:B15) | E15: =C15+3*D15 | F15: =C15-3*D15 | G15: =IF(D15=0,"",(B15-C15)/D15) | H15: =MEDIAN(B2:B15) | I15: =MEDIAN(ABS(B2:B15-H15)) | J15: =IF(I15=0,"",0.6745*(B15-H15)/I15) | K15: =0.2*B15+0.8*K14 | L15: =C15+3*D15*SQRT(0.2/(2-0.2)) | M15: =C15-3*D15*SQRT(0.2/(2-0.2)) | N15: =MAX(0,N14+(B15-C15-0.5*D15)) | O15: =MIN(0,O14+(B15-C15+0.5*D15)) | P15: =IF(ABS(G15)>1,P14+1,0) | Q15: =IFS(OR(ABS(G15)>3,N15>5*D15,ABS(O15)>5*D15,P15>=5),"CRITICAL",OR(ABS(G15)>2,P15>=3,ABS(J15)>3.5),"EARLY WARNING",ABS(G15)>1,"WATCH",TRUE,"NORMAL")
A16: 45041 | B16: =Raw_Data!B16 | C16: =AVERAGE(B2:B16) | D16: =STDEV.S(B2:B16) | E16: =C16+3*D16 | F16: =C16-3*D16 | G16: =IF(D16=0,"",(B16-C16)/D16) | H16: =MEDIAN(B2:B16) | I16: =MEDIAN(ABS(B2:B16-H16)) | J16: =IF(I16=0,"",0.6745*(B16-H16)/I16) | K16: =0.2*B16+0.8*K15 | L16: =C16+3*D16*SQRT(0.2/(2-0.2)) | M16: =C16-3*D16*SQRT(0.2/(2-0.2)) | N16: =MAX(0,N15+(B16-C16-0.5*D16)) | O16: =MIN(0,O15+(B16-C16+0.5*D16)) | P16: =IF(ABS(G16)>1,P15+1,0) | Q16: =IFS(OR(ABS(G16)>3,N16>5*D16,ABS(O16)>5*D16,P16>=5),"CRITICAL",OR(ABS(G16)>2,P16>=3,ABS(J16)>3.5),"EARLY WARNING",ABS(G16)>1,"WATCH",TRUE,"NORMAL")
A17: 45042 | B17: =Raw_Data!B17 | C17: =AVERAGE(B2:B17) | D17: =STDEV.S(B2:B17) | E17: =C17+3*D17 | F17: =C17-3*D17 | G17: =IF(D17=0,"",(B17-C17)/D17) | H17: =MEDIAN(B2:B17) | I17: =MEDIAN(ABS(B2:B17-H17)) | J17: =IF(I17=0,"",0.6745*(B17-H17)/I17) | K17: =0.2*B17+0.8*K16 | L17: =C17+3*D17*SQRT(0.2/(2-0.2)) | M17: =C17-3*D17*SQRT(0.2/(2-0.2)) | N17: =MAX(0,N16+(B17-C17-0.5*D17)) | O17: =MIN(0,O16+(B17-C17+0.5*D17)) | P17: =IF(ABS(G17)>1,P16+1,0) | Q17: =IFS(OR(ABS(G17)>3,N17>5*D17,ABS(O17)>5*D17,P17>=5),"CRITICAL",OR(ABS(G17)>2,P17>=3,ABS(J17)>3.5),"EARLY WARNING",ABS(G17)>1,"WATCH",TRUE,"NORMAL")
A18: 45043 | B18: =Raw_Data!B18 | C18: =AVERAGE(B2:B18) | D18: =STDEV.S(B2:B18) | E18: =C18+3*D18 | F18: =C18-3*D18 | G18: =IF(D18=0,"",(B18-C18)/D18) | H18: =MEDIAN(B2:B18) | I18: =MEDIAN(ABS(B2:B18-H18)) | J18: =IF(I18=0,"",0.6745*(B18-H18)/I18) | K18: =0.2*B18+0.8*K17 | L18: =C18+3*D18*SQRT(0.2/(2-0.2)) | M18: =C18-3*D18*SQRT(0.2/(2-0.2)) | N18: =MAX(0,N17+(B18-C18-0.5*D18)) | O18: =MIN(0,O17+(B18-C18+0.5*D18)) | P18: =IF(ABS(G18)>1,P17+1,0) | Q18: =IFS(OR(ABS(G18)>3,N18>5*D18,ABS(O18)>5*D18,P18>=5),"CRITICAL",OR(ABS(G18)>2,P18>=3,ABS(J18)>3.5),"EARLY WARNING",ABS(G18)>1,"WATCH",TRUE,"NORMAL")
A19: 45044 | B19: =Raw_Data!B19 | C19: =AVERAGE(B2:B19) | D19: =STDEV.S(B2:B19) | E19: =C19+3*D19 | F19: =C19-3*D19 | G19: =IF(D19=0,"",(B19-C19)/D19) | H19: =MEDIAN(B2:B19) | I19: =MEDIAN(ABS(B2:B19-H19)) | J19: =IF(I19=0,"",0.6745*(B19-H19)/I19) | K19: =0.2*B19+0.8*K18 | L19: =C19+3*D19*SQRT(0.2/(2-0.2)) | M19: =C19-3*D19*SQRT(0.2/(2-0.2)) | N19: =MAX(0,N18+(B19-C19-0.5*D19)) | O19: =MIN(0,O18+(B19-C19+0.5*D19)) | P19: =IF(ABS(G19)>1,P18+1,0) | Q19: =IFS(OR(ABS(G19)>3,N19>5*D19,ABS(O19)>5*D19,P19>=5),"CRITICAL",OR(ABS(G19)>2,P19>=3,ABS(J19)>3.5),"EARLY WARNING",ABS(G19)>1,"WATCH",TRUE,"NORMAL")
A20: 45045 | B20: =Raw_Data!B20 | C20: =AVERAGE(B2:B20) | D20: =STDEV.S(B2:B20) | E20: =C20+3*D20 | F20: =C20-3*D20 | G20: =IF(D20=0,"",(B20-C20)/D20) | H20: =MEDIAN(B2:B20) | I20: =MEDIAN(ABS(B2:B20-H20)) | J20: =IF(I20=0,"",0.6745*(B20-H20)/I20) | K20: =0.2*B20+0.8*K19 | L20: =C20+3*D20*SQRT(0.2/(2-0.2)) | M20: =C20-3*D20*SQRT(0.2/(2-0.2)) | N20: =MAX(0,N19+(B20-C20-0.5*D20)) | O20: =MIN(0,O19+(B20-C20+0.5*D20)) | P20: =IF(ABS(G20)>1,P19+1,0) | Q20: =IFS(OR(ABS(G20)>3,N20>5*D20,ABS(O20)>5*D20,P20>=5),"CRITICAL",OR(ABS(G20)>2,P20>=3,ABS(J20)>3.5),"EARLY WARNING",ABS(G20)>1,"WATCH",TRUE,"NORMAL")
A21: 45046 | B21: =Raw_Data!B21 | C21: =AVERAGE(B2:B21) | D21: =STDEV.S(B2:B21) | E21: =C21+3*D21 | F21: =C21-3*D21 | G21: =IF(D21=0,"",(B21-C21)/D21) | H21: =MEDIAN(B2:B21) | I21: =MEDIAN(ABS(B2:B21-H21)) | J21: =IF(I21=0,"",0.6745*(B21-H21)/I21) | K21: =0.2*B21+0.8*K20 | L21: =C21+3*D21*SQRT(0.2/(2-0.2)) | M21: =C21-3*D21*SQRT(0.2/(2-0.2)) | N21: =MAX(0,N20+(B21-C21-0.5*D21)) | O21: =MIN(0,O20+(B21-C21+0.5*D21)) | P21: =IF(ABS(G21)>1,P20+1,0) | Q21: =IFS(OR(ABS(G21)>3,N21>5*D21,ABS(O21)>5*D21,P21>=5),"CRITICAL",OR(ABS(G21)>2,P21>=3,ABS(J21)>3.5),"EARLY WARNING",ABS(G21)>1,"WATCH",TRUE,"NORMAL")
A22: 45047 | B22: =Raw_Data!B22 | C22: =AVERAGE(B2:B22) | D22: =STDEV.S(B2:B22) | E22: =C22+3*D22 | F22: =C22-3*D22 | G22: =IF(D22=0,"",(B22-C22)/D22) | H22: =MEDIAN(B2:B22) | I22: =MEDIAN(ABS(B2:B22-H22)) | J22: =IF(I22=0,"",0.6745*(B22-H22)/I22) | K22: =0.2*B22+0.8*K21 | L22: =C22+3*D22*SQRT(0.2/(2-0.2)) | M22: =C22-3*D22*SQRT(0.2/(2-0.2)) | N22: =MAX(0,N21+(B22-C22-0.5*D22)) | O22: =MIN(0,O21+(B22-C22+0.5*D22)) | P22: =IF(ABS(G22)>1,P21+1,0) | Q22: =IFS(OR(ABS(G22)>3,N22>5*D22,ABS(O22)>5*D22,P22>=5),"CRITICAL",OR(ABS(G22)>2,P22>=3,ABS(J22)>3.5),"EARLY WARNING",ABS(G22)>1,"WATCH",TRUE,"NORMAL")
A23: 45048 | B23: =Raw_Data!B23 | C23: =AVERAGE(B2:B23) | D23: =STDEV.S(B2:B23) | E23: =C23+3*D23 | F23: =C23-3*D23 | G23: =IF(D23=0,"",(B23-C23)/D23) | H23: =MEDIAN(B2:B23) | I23: =MEDIAN(ABS(B2:B23-H23)) | J23: =IF(I23=0,"",0.6745*(B23-H23)/I23) | K23: =0.2*B23+0.8*K22 | L23: =C23+3*D23*SQRT(0.2/(2-0.2)) | M23: =C23-3*D23*SQRT(0.2/(2-0.2)) | N23: =MAX(0,N22+(B23-C23-0.5*D23)) | O23: =MIN(0,O22+(B23-C23+0.5*D23)) | P23: =IF(ABS(G23)>1,P22+1,0) | Q23: =IFS(OR(ABS(G23)>3,N23>5*D23,ABS(O23)>5*D23,P23>=5),"CRITICAL",OR(ABS(G23)>2,P23>=3,ABS(J23)>3.5),"EARLY WARNING",ABS(G23)>1,"WATCH",TRUE,"NORMAL")
A24: 45049 | B24: =Raw_Data!B24 | C24: =AVERAGE(B2:B24) | D24: =STDEV.S(B2:B24) | E24: =C24+3*D24 | F24: =C24-3*D24 | G24: =IF(D24=0,"",(B24-C24)/D24) | H24: =MEDIAN(B2:B24) | I24: =MEDIAN(ABS(B2:B24-H24)) | J24: =IF(I24=0,"",0.6745*(B24-H24)/I24) | K24: =0.2*B24+0.8*K23 | L24: =C24+3*D24*SQRT(0.2/(2-0.2)) | M24: =C24-3*D24*SQRT(0.2/(2-0.2)) | N24: =MAX(0,N23+(B24-C24-0.5*D24)) | O24: =MIN(0,O23+(B24-C24+0.5*D24)) | P24: =IF(ABS(G24)>1,P23+1,0) | Q24: =IFS(OR(ABS(G24)>3,N24>5*D24,ABS(O24)>5*D24,P24>=5),"CRITICAL",OR(ABS(G24)>2,P24>=3,ABS(J24)>3.5),"EARLY WARNING",ABS(G24)>1,"WATCH",TRUE,"NORMAL")
A25: 45050 | B25: =Raw_Data!B25 | C25: =AVERAGE(B2:B25) | D25: =STDEV.S(B2:B25) | E25: =C25+3*D25 | F25: =C25-3*D25 | G25: =IF(D25=0,"",(B25-C25)/D25) | H25: =MEDIAN(B2:B25) | I25: =MEDIAN(ABS(B2:B25-H25)) | J25: =IF(I25=0,"",0.6745*(B25-H25)/I25) | K25: =0.2*B25+0.8*K24 | L25: =C25+3*D25*SQRT(0.2/(2-0.2)) | M25: =C25-3*D25*SQRT(0.2/(2-0.2)) | N25: =MAX(0,N24+(B25-C25-0.5*D25)) | O25: =MIN(0,O24+(B25-C25+0.5*D25)) | P25: =IF(ABS(G25)>1,P24+1,0) | Q25: =IFS(OR(ABS(G25)>3,N25>5*D25,ABS(O25)>5*D25,P25>=5),"CRITICAL",OR(ABS(G25)>2,P25>=3,ABS(J25)>3.5),"EARLY WARNING",ABS(G25)>1,"WATCH",TRUE,"NORMAL")
A26: 45051 | B26: =Raw_Data!B26 | C26: =AVERAGE(B2:B26) | D26: =STDEV.S(B2:B26) | E26: =C26+3*D26 | F26: =C26-3*D26 | G26: =IF(D26=0,"",(B26-C26)/D26) | H26: =MEDIAN(B2:B26) | I26: =MEDIAN(ABS(B2:B26-H26)) | J26: =IF(I26=0,"",0.6745*(B26-H26)/I26) | K26: =0.2*B26+0.8*K25 | L26: =C26+3*D26*SQRT(0.2/(2-0.2)) | M26: =C26-3*D26*SQRT(0.2/(2-0.2)) | N26: =MAX(0,N25+(B26-C26-0.5*D26)) | O26: =MIN(0,O25+(B26-C26+0.5*D26)) | P26: =IF(ABS(G26)>1,P25+1,0) | Q26: =IFS(OR(ABS(G26)>3,N26>5*D26,ABS(O26)>5*D26,P26>=5),"CRITICAL",OR(ABS(G26)>2,P26>=3,ABS(J26)>3.5),"EARLY WARNING",ABS(G26)>1,"WATCH",TRUE,"NORMAL")
A27: 45052 | B27: =Raw_Data!B27 | C27: =AVERAGE(B2:B27) | D27: =STDEV.S(B2:B27) | E27: =C27+3*D27 | F27: =C27-3*D27 | G27: =IF(D27=0,"",(B27-C27)/D27) | H27: =MEDIAN(B2:B27) | I27: =MEDIAN(ABS(B2:B27-H27)) | J27: =IF(I27=0,"",0.6745*(B27-H27)/I27) | K27: =0.2*B27+0.8*K26 | L27: =C27+3*D27*SQRT(0.2/(2-0.2)) | M27: =C27-3*D27*SQRT(0.2/(2-0.2)) | N27: =MAX(0,N26+(B27-C27-0.5*D27)) | O27: =MIN(0,O26+(B27-C27+0.5*D27)) | P27: =IF(ABS(G27)>1,P26+1,0) | Q27: =IFS(OR(ABS(G27)>3,N27>5*D27,ABS(O27)>5*D27,P27>=5),"CRITICAL",OR(ABS(G27)>2,P27>=3,ABS(J27)>3.5),"EARLY WARNING",ABS(G27)>1,"WATCH",TRUE,"NORMAL")
A28: 45053 | B28: =Raw_Data!B28 | C28: =AVERAGE(B2:B28) | D28: =STDEV.S(B2:B28) | E28: =C28+3*D28 | F28: =C28-3*D28 | G28: =IF(D28=0,"",(B28-C28)/D28) | H28: =MEDIAN(B2:B28) | I28: =MEDIAN(ABS(B2:B28-H28)) | J28: =IF(I28=0,"",0.6745*(B28-H28)/I28) | K28: =0.2*B28+0.8*K27 | L28: =C28+3*D28*SQRT(0.2/(2-0.2)) | M28: =C28-3*D28*SQRT(0.2/(2-0.2)) | N28: =MAX(0,N27+(B28-C28-0.5*D28)) | O28: =MIN(0,O27+(B28-C28+0.5*D28)) | P28: =IF(ABS(G28)>1,P27+1,0) | Q28: =IFS(OR(ABS(G28)>3,N28>5*D28,ABS(O28)>5*D28,P28>=5),"CRITICAL",OR(ABS(G28)>2,P28>=3,ABS(J28)>3.5),"EARLY WARNING",ABS(G28)>1,"WATCH",TRUE,"NORMAL")
A29: 45054 | B29: =Raw_Data!B29 | C29: =AVERAGE(B2:B29) | D29: =STDEV.S(B2:B29) | E29: =C29+3*D29 | F29: =C29-3*D29 | G29: =IF(D29=0,"",(B29-C29)/D29) | H29: =MEDIAN(B2:B29) | I29: =MEDIAN(ABS(B2:B29-H29)) | J29: =IF(I29=0,"",0.6745*(B29-H29)/I29) | K29: =0.2*B29+0.8*K28 | L29: =C29+3*D29*SQRT(0.2/(2-0.2)) | M29: =C29-3*D29*SQRT(0.2/(2-0.2)) | N29: =MAX(0,N28+(B29-C29-0.5*D29)) | O29: =MIN(0,O28+(B29-C29+0.5*D29)) | P29: =IF(ABS(G29)>1,P28+1,0) | Q29: =IFS(OR(ABS(G29)>3,N29>5*D29,ABS(O29)>5*D29,P29>=5),"CRITICAL",OR(ABS(G29)>2,P29>=3,ABS(J29)>3.5),"EARLY WARNING",ABS(G29)>1,"WATCH",TRUE,"NORMAL")
A30: 45055 | B30: =Raw_Data!B30 | C30: =AVERAGE(B2:B30) | D30: =STDEV.S(B2:B30) | E30: =C30+3*D30 | F30: =C30-3*D30 | G30: =IF(D30=0,"",(B30-C30)/D30) | H30: =MEDIAN(B2:B30) | I30: =MEDIAN(ABS(B2:B30-H30)) | J30: =IF(I30=0,"",0.6745*(B30-H30)/I30) | K30: =0.2*B30+0.8*K29 | L30: =C30+3*D30*SQRT(0.2/(2-0.2)) | M30: =C30-3*D30*SQRT(0.2/(2-0.2)) | N30: =MAX(0,N29+(B30-C30-0.5*D30)) | O30: =MIN(0,O29+(B30-C30+0.5*D30)) | P30: =IF(ABS(G30)>1,P29+1,0) | Q30: =IFS(OR(ABS(G30)>3,N30>5*D30,ABS(O30)>5*D30,P30>=5),"CRITICAL",OR(ABS(G30)>2,P30>=3,ABS(J30)>3.5),"EARLY WARNING",ABS(G30)>1,"WATCH",TRUE,"NORMAL")
A31: 45056 | B31: =Raw_Data!B31 | C31: =AVERAGE(B2:B31) | D31: =STDEV.S(B2:B31) | E31: =C31+3*D31 | F31: =C31-3*D31 | G31: =IF(D31=0,"",(B31-C31)/D31) | H31: =MEDIAN(B2:B31) | I31: =MEDIAN(ABS(B2:B31-H31)) | J31: =IF(I31=0,"",0.6745*(B31-H31)/I31) | K31: =0.2*B31+0.8*K30 | L31: =C31+3*D31*SQRT(0.2/(2-0.2)) | M31: =C31-3*D31*SQRT(0.2/(2-0.2)) | N31: =MAX(0,N30+(B31-C31-0.5*D31)) | O31: =MIN(0,O30+(B31-C31+0.5*D31)) | P31: =IF(ABS(G31)>1,P30+1,0) | Q31: =IFS(OR(ABS(G31)>3,N31>5*D31,ABS(O31)>5*D31,P31>=5),"CRITICAL",OR(ABS(G31)>2,P31>=3,ABS(J31)>3.5),"EARLY WARNING",ABS(G31)>1,"WATCH",TRUE,"NORMAL")
A32: 45057 | B32: =Raw_Data!B32 | C32: =AVERAGE(B3:B32) | D32: =STDEV.S(B3:B32) | E32: =C32+3*D32 | F32: =C32-3*D32 | G32: =IF(D32=0,"",(B32-C32)/D32) | H32: =MEDIAN(B3:B32) | I32: =MEDIAN(ABS(B3:B32-H32)) | J32: =IF(I32=0,"",0.6745*(B32-H32)/I32) | K32: =0.2*B32+0.8*K31 | L32: =C32+3*D32*SQRT(0.2/(2-0.2)) | M32: =C32-3*D32*SQRT(0.2/(2-0.2)) | N32: =MAX(0,N31+(B32-C32-0.5*D32)) | O32: =MIN(0,O31+(B32-C32+0.5*D32)) | P32: =IF(ABS(G32)>1,P31+1,0) | Q32: =IFS(OR(ABS(G32)>3,N32>5*D32,ABS(O32)>5*D32,P32>=5),"CRITICAL",OR(ABS(G32)>2,P32>=3,ABS(J32)>3.5),"EARLY WARNING",ABS(G32)>1,"WATCH",TRUE,"NORMAL")
A33: 45058 | B33: =Raw_Data!B33 | C33: =AVERAGE(B4:B33) | D33: =STDEV.S(B4:B33) | E33: =C33+3*D33 | F33: =C33-3*D33 | G33: =IF(D33=0,"",(B33-C33)/D33) | H33: =MEDIAN(B4:B33) | I33: =MEDIAN(ABS(B4:B33-H33)) | J33: =IF(I33=0,"",0.6745*(B33-H33)/I33) | K33: =0.2*B33+0.8*K32 | L33: =C33+3*D33*SQRT(0.2/(2-0.2)) | M33: =C33-3*D33*SQRT(0.2/(2-0.2)) | N33: =MAX(0,N32+(B33-C33-0.5*D33)) | O33: =MIN(0,O32+(B33-C33+0.5*D33)) | P33: =IF(ABS(G33)>1,P32+1,0) | Q33: =IFS(OR(ABS(G33)>3,N33>5*D33,ABS(O33)>5*D33,P33>=5),"CRITICAL",OR(ABS(G33)>2,P33>=3,ABS(J33)>3.5),"EARLY WARNING",ABS(G33)>1,"WATCH",TRUE,"NORMAL")
A34: 45059 | B34: =Raw_Data!B34 | C34: =AVERAGE(B5:B34) | D34: =STDEV.S(B5:B34) | E34: =C34+3*D34 | F34: =C34-3*D34 | G34: =IF(D34=0,"",(B34-C34)/D34) | H34: =MEDIAN(B5:B34) | I34: =MEDIAN(ABS(B5:B34-H34)) | J34: =IF(I34=0,"",0.6745*(B34-H34)/I34) | K34: =0.2*B34+0.8*K33 | L34: =C34+3*D34*SQRT(0.2/(2-0.2)) | M34: =C34-3*D34*SQRT(0.2/(2-0.2)) | N34: =MAX(0,N33+(B34-C34-0.5*D34)) | O34: =MIN(0,O33+(B34-C34+0.5*D34)) | P34: =IF(ABS(G34)>1,P33+1,0) | Q34: =IFS(OR(ABS(G34)>3,N34>5*D34,ABS(O34)>5*D34,P34>=5),"CRITICAL",OR(ABS(G34)>2,P34>=3,ABS(J34)>3.5),"EARLY WARNING",ABS(G34)>1,"WATCH",TRUE,"NORMAL")
A35: 45060 | B35: =Raw_Data!B35 | C35: =AVERAGE(B6:B35) | D35: =STDEV.S(B6:B35) | E35: =C35+3*D35 | F35: =C35-3*D35 | G35: =IF(D35=0,"",(B35-C35)/D35) | H35: =MEDIAN(B6:B35) | I35: =MEDIAN(ABS(B6:B35-H35)) | J35: =IF(I35=0,"",0.6745*(B35-H35)/I35) | K35: =0.2*B35+0.8*K34 | L35: =C35+3*D35*SQRT(0.2/(2-0.2)) | M35: =C35-3*D35*SQRT(0.2/(2-0.2)) | N35: =MAX(0,N34+(B35-C35-0.5*D35)) | O35: =MIN(0,O34+(B35-C35+0.5*D35)) | P35: =IF(ABS(G35)>1,P34+1,0) | Q35: =IFS(OR(ABS(G35)>3,N35>5*D35,ABS(O35)>5*D35,P35>=5),"CRITICAL",OR(ABS(G35)>2,P35>=3,ABS(J35)>3.5),"EARLY WARNING",ABS(G35)>1,"WATCH",TRUE,"NORMAL")
A36: 45061 | B36: =Raw_Data!B36 | C36: =AVERAGE(B7:B36) | D36: =STDEV.S(B7:B36) | E36: =C36+3*D36 | F36: =C36-3*D36 | G36: =IF(D36=0,"",(B36-C36)/D36) | H36: =MEDIAN(B7:B36) | I36: =MEDIAN(ABS(B7:B36-H36)) | J36: =IF(I36=0,"",0.6745*(B36-H36)/I36) | K36: =0.2*B36+0.8*K35 | L36: =C36+3*D36*SQRT(0.2/(2-0.2)) | M36: =C36-3*D36*SQRT(0.2/(2-0.2)) | N36: =MAX(0,N35+(B36-C36-0.5*D36)) | O36: =MIN(0,O35+(B36-C36+0.5*D36)) | P36: =IF(ABS(G36)>1,P35+1,0) | Q36: =IFS(OR(ABS(G36)>3,N36>5*D36,ABS(O36)>5*D36,P36>=5),"CRITICAL",OR(ABS(G36)>2,P36>=3,ABS(J36)>3.5),"EARLY WARNING",ABS(G36)>1,"WATCH",TRUE,"NORMAL")
A37: 45062 | B37: =Raw_Data!B37 | C37: =AVERAGE(B8:B37) | D37: =STDEV.S(B8:B37) | E37: =C37+3*D37 | F37: =C37-3*D37 | G37: =IF(D37=0,"",(B37-C37)/D37) | H37: =MEDIAN(B8:B37) | I37: =MEDIAN(ABS(B8:B37-H37)) | J37: =IF(I37=0,"",0.6745*(B37-H37)/I37) | K37: =0.2*B37+0.8*K36 | L37: =C37+3*D37*SQRT(0.2/(2-0.2)) | M37: =C37-3*D37*SQRT(0.2/(2-0.2)) | N37: =MAX(0,N36+(B37-C37-0.5*D37)) | O37: =MIN(0,O36+(B37-C37+0.5*D37)) | P37: =IF(ABS(G37)>1,P36+1,0) | Q37: =IFS(OR(ABS(G37)>3,N37>5*D37,ABS(O37)>5*D37,P37>=5),"CRITICAL",OR(ABS(G37)>2,P37>=3,ABS(J37)>3.5),"EARLY WARNING",ABS(G37)>1,"WATCH",TRUE,"NORMAL")
A38: 45063 | B38: =Raw_Data!B38 | C38: =AVERAGE(B9:B38) | D38: =STDEV.S(B9:B38) | E38: =C38+3*D38 | F38: =C38-3*D38 | G38: =IF(D38=0,"",(B38-C38)/D38) | H38: =MEDIAN(B9:B38) | I38: =MEDIAN(ABS(B9:B38-H38)) | J38: =IF(I38=0,"",0.6745*(B38-H38)/I38) | K38: =0.2*B38+0.8*K37 | L38: =C38+3*D38*SQRT(0.2/(2-0.2)) | M38: =C38-3*D38*SQRT(0.2/(2-0.2)) | N38: =MAX(0,N37+(B38-C38-0.5*D38)) | O38: =MIN(0,O37+(B38-C38+0.5*D38)) | P38: =IF(ABS(G38)>1,P37+1,0) | Q38: =IFS(OR(ABS(G38)>3,N38>5*D38,ABS(O38)>5*D38,P38>=5),"CRITICAL",OR(ABS(G38)>2,P38>=3,ABS(J38)>3.5),"EARLY WARNING",ABS(G38)>1,"WATCH",TRUE,"NORMAL")
A39: 45064 | B39: =Raw_Data!B39 | C39: =AVERAGE(B10:B39) | D39: =STDEV.S(B10:B39) | E39: =C39+3*D39 | F39: =C39-3*D39 | G39: =IF(D39=0,"",(B39-C39)/D39) | H39: =MEDIAN(B10:B39) | I39: =MEDIAN(ABS(B10:B39-H39)) | J39: =IF(I39=0,"",0.6745*(B39-H39)/I39) | K39: =0.2*B39+0.8*K38 | L39: =C39+3*D39*SQRT(0.2/(2-0.2)) | M39: =C39-3*D39*SQRT(0.2/(2-0.2)) | N39: =MAX(0,N38+(B39-C39-0.5*D39)) | O39: =MIN(0,O38+(B39-C39+0.5*D39)) | P39: =IF(ABS(G39)>1,P38+1,0) | Q39: =IFS(OR(ABS(G39)>3,N39>5*D39,ABS(O39)>5*D39,P39>=5),"CRITICAL",OR(ABS(G39)>2,P39>=3,ABS(J39)>3.5),"EARLY WARNING",ABS(G39)>1,"WATCH",TRUE,"NORMAL")
A40: 45065 | B40: =Raw_Data!B40 | C40: =AVERAGE(B11:B40) | D40: =STDEV.S(B11:B40) | E40: =C40+3*D40 | F40: =C40-3*D40 | G40: =IF(D40=0,"",(B40-C40)/D40) | H40: =MEDIAN(B11:B40) | I40: =MEDIAN(ABS(B11:B40-H40)) | J40: =IF(I40=0,"",0.6745*(B40-H40)/I40) | K40: =0.2*B40+0.8*K39 | L40: =C40+3*D40*SQRT(0.2/(2-0.2)) | M40: =C40-3*D40*SQRT(0.2/(2-0.2)) | N40: =MAX(0,N39+(B40-C40-0.5*D40)) | O40: =MIN(0,O39+(B40-C40+0.5*D40)) | P40: =IF(ABS(G40)>1,P39+1,0) | Q40: =IFS(OR(ABS(G40)>3,N40>5*D40,ABS(O40)>5*D40,P40>=5),"CRITICAL",OR(ABS(G40)>2,P40>=3,ABS(J40)>3.5),"EARLY WARNING",ABS(G40)>1,"WATCH",TRUE,"NORMAL")
...

Sheet Alert_Log
A1: Date | B1: Value | C1: Rolling_Mean_30 | D1: Z_Score | E1: Robust_Z | F1: Consec_Breach | G1: Status
A2: =IFERROR(SORT(FILTER(HSTACK(Analysis!A2:A644,Analysis!B2:B644,Analysis!C2:C644,Analysis!G2:G644,Analysis!J2:J644,Analysis!P2:P644,Analysis!Q2:Q644),(Analysis!Q2:Q644<>"NORMAL")*(Analysis!Q2:Q644<>"Insufficient History")),1,-1),"No active warnings")
